Workbook
Name inp_scenario: Inputs_Drivers!$C$4
Name inp_scen_idx: Inputs_Drivers!$C$5
Name inp_logos_ent: Inputs_Drivers!$C$9
Name inp_logos_mid: Inputs_Drivers!$C$10
Name inp_logo_growth: Inputs_Drivers!$C$11
Name inp_acv_ent: Inputs_Drivers!$C$13
Name inp_acv_mid: Inputs_Drivers!$C$14
Name inp_price_uplift: Inputs_Drivers!$C$15
Name inp_exp_ent: Inputs_Drivers!$C$17
Name inp_exp_mid: Inputs_Drivers!$C$18
Name inp_churn_ent: Inputs_Drivers!$C$19
Name inp_churn_mid: Inputs_Drivers!$C$20
Name inp_hires_rd: Inputs_Drivers!$C$22
Name inp_hires_sm: Inputs_Drivers!$C$23
Name inp_hires_ga: Inputs_Drivers!$C$24
Name inp_hires_cs: Inputs_Drivers!$C$25
Name inp_dso: Inputs_Drivers!$C$27
Name inp_model_start: Inputs_Drivers!$C$29
Name inp_arr_open_ent: Inputs_Drivers!$C$30
Name inp_arr_open_mid: Inputs_Drivers!$C$31
Name inp_cust_open_ent: Inputs_Drivers!$C$32
Name inp_cust_open_mid: Inputs_Drivers!$C$33
Name inp_open_cash: Inputs_Drivers!$C$34
Name inp_open_ar: Inputs_Drivers!$C$35
Name inp_open_ppe: Inputs_Drivers!$C$36
Name inp_open_ap: Inputs_Drivers!$C$37
Name inp_open_defrev_impl: Inputs_Drivers!$C$38
Name inp_heads_open_rd: Inputs_Drivers!$C$40
Name inp_heads_open_sm: Inputs_Drivers!$C$41
Name inp_heads_open_ga: Inputs_Drivers!$C$42
Name inp_heads_open_cs: Inputs_Drivers!$C$43
Name inp_sal_rd: Inputs_Drivers!$C$44
Name inp_sal_sm: Inputs_Drivers!$C$45
Name inp_sal_ga: Inputs_Drivers!$C$46
Name inp_sal_cs: Inputs_Drivers!$C$47
Name inp_merit: Inputs_Drivers!$C$48
Name inp_marketing_m: Inputs_Drivers!$C$50
Name inp_rd_other_m: Inputs_Drivers!$C$51
Name inp_ga_other_m: Inputs_Drivers!$C$52
Name inp_commission_pct: Inputs_Drivers!$C$53
Name inp_capitalise_commission: Inputs_Drivers!$C$54
Name inp_cc_life: Inputs_Drivers!$C$55
Name inp_open_cca: Inputs_Drivers!$C$56
Name inp_host_ent: Inputs_Drivers!$C$57
Name inp_host_mid: Inputs_Drivers!$C$58
Name inp_licence_pct: Inputs_Drivers!$C$59
Name inp_impl_fee_pct: Inputs_Drivers!$C$60
Name inp_services_cost_pct: Inputs_Drivers!$C$61
Name inp_v_logos: Inputs_Drivers!$C$63
Name inp_v_exp: Inputs_Drivers!$C$64
Name inp_v_churn: Inputs_Drivers!$C$65
Name inp_ma_syn_achieved: Inputs_Drivers!$C$66
Name inp_ma_include: Inputs_Drivers!$C$68
Name inp_ma_offer_mult: Inputs_Drivers!$C$69
Name inp_ma_debt: Inputs_Drivers!$C$70
Name inp_ma_loan_rate: Inputs_Drivers!$C$71
Name inp_ma_deal_cost_pct: Inputs_Drivers!$C$72
Name inp_ma_integration_total: Inputs_Drivers!$C$73
Name inp_ma_integration_months: Inputs_Drivers!$C$74
Name inp_ma_xsell_logos_m: Inputs_Drivers!$C$75

Sheet Cover
A1: Keel - SaaS operating model for Northgate Controls Ltd
A2: Synthetic data. A formula-driven FP&A model: ARR build, revenue recognition, three statements, SaaS unit economics.
A4: Master check | B4: =Checks!E46
A5: Live scenario | B5: =inp_scenario
A6: Units | B6: GBP thousands unless stated. 24 monthly periods from the model start date, FY1 and FY2 annual columns.
A7: Outlier warnings | B7: =chk_warnings&" series flagged for review (see Checks)"
A8: Colour convention | B8: Blue = typed input
B9: Black = formula
B10: Green = link to another tab
A12: Model map
A13: Inputs_Drivers | B13: Named inputs (inp_*). Scenario selector. Live scenario values | C13: Phase 1
A14: Inputs_Scenarios | B14: Base / Upside / Downside / Custom values | C14: Phase 1
A15: Rev_Build | B15: ARR waterfall and customers by segment | C15: Phase 1
A16: Rev_Rec | B16: Billings, ratable revenue, deferred revenue, receivables | C16: Phase 1
A17: Headcount_Opex | B17: Headcount, payroll, opex by function | C17: Phase 1
A18: COGS | B18: Hosting, licences, support; gross margin by stream | C18: Phase 1
A19: IS / BS / CF | B19: Integrated three statements (balance check on BS) | C19: Phase 1
A20: SaaS_Metrics | B20: ARR bridge, NRR, GRR, CAC, payback, LTV/CAC, burn multiple, runway, Rule of 40 | C20: Phase 1
A21: Checks | B21: Integrity tests and master flag | C21: Phase 1
A22: Contract_Costs | B22: Capitalised sales commission (IFRS 15), amortisation, S&M charge | C22: Phase 2
A23: Inputs_Budget, Budget_vs_Forecast | B23: Board budget as received; mapped variances and three bridges (ARR, revenue, EBITDA) | C23: Phase 2
A24: LT_Model | B24: Five-year view: years 1-2 linked, years 3-5 driver-based | C24: Phase 2
... A30: MA_Target, MA_Valuation, MA_PPA, MA_ProForma, MA_Returns | B30: Vaultline acquisition module | C30: Phase 3 (not built)
A32: Version log
A33: v0.1 | B33: Phase 1 MVP: ARR build, rev rec, opex, COGS, three statements, SaaS metrics, scenarios (Base/Upside/Downside/Custom), checks.
A34: v0.2 | B34: Phase 2: Contract_Costs, budget and variance bridges, LT_Model, Lever_Analysis, Sensitivity, Business_Review. Fixed FY opening-balance columns.
A35: v0.3 | B35: Phase 3: Vaultline acquisition module (MA_* tabs, Inputs_Comps), acquisition scenario drivers, deal outcome in the scenario snapshots.
A36: v0.4 | B36: Phase 4: global tolerance, sign / annual-column / range checks, outlier warnings (validation lives in validation/).
A37: v0.5 | B37: Phase 5: Outputs_Web contract (named out_* ranges, input registry), array formulas replaced by helper rows, named_ranges.json export.

Sheet Inputs_Drivers
A1: Inputs_Drivers - every named input the model (and later the website) reads
A2: Blue = typed input. Green = live value pulled from Inputs_Scenarios for the selected scenario.
A4: Scenario selector | C4: Base | F4: Pick Base, Upside, Downside or Custom.
A5: Scenario index | C5: =MATCH(inp_scenario,Inputs_Scenarios!$C$4:$F$4,0) | F5: Position of the selected scenario in Inputs_Scenarios (1-4).
A7: Driver | B7: Unit | C7: Value | D7: Min | E7: Max | F7: What it drives | G7: Out of range
A8: Growth
A9: New Enterprise logos per month | B9: #/mo | C9: =INDEX(Inputs_Scenarios!$C6:$F6,1,inp_scen_idx) | D9: 0 | E9: 15 | F9: New-logo ARR = logos x ACV. Biggest driver of ARR growth. | G9: =IF(OR(C9<D9,C9>E9),1,0)
A10: New Mid-market logos per month | B10: #/mo | C10: =INDEX(Inputs_Scenarios!$C7:$F7,1,inp_scen_idx) | D10: 0 | E10: 60 | F10: Volume engine for the Mid-market segment. | G10: =IF(OR(C10<D10,C10>E10),1,0)
A11: Annual growth in new-logo volume | B11: % p.a. | C11: =INDEX(Inputs_Scenarios!$C8:$F8,1,inp_scen_idx) | D11: -0.2 | E11: 0.5 | F11: Compounds monthly. Sales capacity proxy in the MVP. | G11: =IF(OR(C11<D11,C11>E11),1,0)
A12: Pricing
A13: Enterprise ACV (new logos) | B13: GBP k | C13: =INDEX(Inputs_Scenarios!$C10:$F10,1,inp_scen_idx) | D13: 50 | E13: 1000 | F13: Average annual contract value of a new Enterprise logo. | G13: =IF(OR(C13<D13,C13>E13),1,0)
A14: Mid-market ACV (new logos) | B14: GBP k | C14: =INDEX(Inputs_Scenarios!$C11:$F11,1,inp_scen_idx) | D14: 5 | E14: 100 | F14: Average annual contract value of a new Mid-market logo. | G14: =IF(OR(C14<D14,C14>E14),1,0)
A15: Annual price uplift on new-logo ACV | B15: % p.a. | C15: =INDEX(Inputs_Scenarios!$C12:$F12,1,inp_scen_idx) | D15: 0 | E15: 0.15 | F15: Applied from month 13, 25, ... to new-logo ACV. | G15: =IF(OR(C15<D15,C15>E15),1,0)
A16: Retention
A17: Enterprise annual expansion | B17: % of ARR | C17: =INDEX(Inputs_Scenarios!$C14:$F14,1,inp_scen_idx) | D17: 0 | E17: 0.5 | F17: Upsell / cross-sell on the existing Enterprise base. | G17: =IF(OR(C17<D17,C17>E17),1,0)
A18: Mid-market annual expansion | B18: % of ARR | C18: =INDEX(Inputs_Scenarios!$C15:$F15,1,inp_scen_idx) | D18: 0 | E18: 0.5 | F18: Upsell on the existing Mid-market base. | G18: =IF(OR(C18<D18,C18>E18),1,0)
A19: Enterprise annual gross churn | B19: % of ARR | C19: =INDEX(Inputs_Scenarios!$C16:$F16,1,inp_scen_idx) | D19: 0 | E19: 0.5 | F19: Lost ARR (incl. contraction) from existing Enterprise customers. | G19: =IF(OR(C19<D19,C19>E19),1,0)
A20: Mid-market annual gross churn | B20: % of ARR | C20: =INDEX(Inputs_Scenarios!$C17:$F17,1,inp_scen_idx) | D20: 0 | E20: 0.5 | F20: Lost ARR (incl. contraction) from existing Mid-market customers. | G20: =IF(OR(C20<D20,C20>E20),1,0)
A21: People (hiring plan)
A22: R&D net hires per month | B22: FTE/mo | C22: =INDEX(Inputs_Scenarios!$C19:$F19,1,inp_scen_idx) | D22: 0 | E22: 10 | F22: Drives R&D payroll. | G22: =IF(OR(C22<D22,C22>E22),1,0)
A23: Sales & Marketing net hires per month | B23: FTE/mo | C23: =INDEX(Inputs_Scenarios!$C20:$F20,1,inp_scen_idx) | D23: 0 | E23: 10 | F23: Drives S&M payroll and CAC. | G23: =IF(OR(C23<D23,C23>E23),1,0)
A24: G&A net hires per month | B24: FTE/mo | C24: =INDEX(Inputs_Scenarios!$C21:$F21,1,inp_scen_idx) | D24: 0 | E24: 5 | F24: Drives G&A payroll. | G24: =IF(OR(C24<D24,C24>E24),1,0)
A25: Customer Success net hires per month | B25: FTE/mo | C25: =INDEX(Inputs_Scenarios!$C22:$F22,1,inp_scen_idx) | D25: 0 | E25: 5 | F25: Drives support payroll in COGS. | G25: =IF(OR(C25<D25,C25>E25),1,0)
A26: Cash
A27: Customer payment terms (DSO) | B27: days | C27: =INDEX(Inputs_Scenarios!$C24:$F24,1,inp_scen_idx) | D27: 0 | E27: 90 | F27: Days to collect an invoice. Drives receivables and cash timing. | G27: =IF(OR(C27<D27,C27>E27),1,0)
A28: Timing and opening position (31 Dec before model start)
A29: Model start date (first forecast month) | B29: date | C29: 46388 | F29: Month 1 of the 24-month forecast.
A30: Opening ARR - Enterprise | B30: GBP k | C30: 26000 | D30: 0 | E30: 200000 | F30: Contracted ARR at the opening date. | G30: =IF(OR(C30<D30,C30>E30),1,0)
A31: Opening ARR - Mid-market | B31: GBP k | C31: 14000 | D31: 0 | E31: 200000 | F31: Contracted ARR at the opening date. | G31: =IF(OR(C31<D31,C31>E31),1,0)
A32: Opening customers - Enterprise | B32: # | C32: 130 | D32: 0 | E32: 5000 | F32: Logo count at the opening date. | G32: =IF(OR(C32<D32,C32>E32),1,0)
A33: Opening customers - Mid-market | B33: # | C33: 560 | D33: 0 | E33: 20000 | F33: Logo count at the opening date. | G33: =IF(OR(C33<D33,C33>E33),1,0)
A34: Opening cash | B34: GBP k | C34: 24000 | D34: 0 | E34: 500000 | F34: Cash at the opening date. | G34: =IF(OR(C34<D34,C34>E34),1,0)
A35: Opening trade receivables | B35: GBP k | C35: 5500 | D35: 0 | E35: 100000 | F35: About 1.5 months of billings. | G35: =IF(OR(C35<D35,C35>E35),1,0)
A36: Opening PP&E (net) | B36: GBP k | C36: 2500 | D36: 0 | E36: 100000 | F36: Net book value at the opening date. | G36: =IF(OR(C36<D36,C36>E36),1,0)
A37: Opening trade payables | B37: GBP k | C37: 1100 | D37: 0 | E37: 100000 | F37: About one month of non-payroll spend. | G37: =IF(OR(C37<D37,C37>E37),1,0)
A38: Opening deferred implementation revenue | B38: GBP k | C38: 0 | D38: 0 | E38: 10000 | F38: Subscription deferred revenue is derived from the billing history. | G38: =IF(OR(C38<D38,C38>E38),1,0)
A39: People (static)
A40: Opening headcount - R&D | B40: FTE | C40: 150 | D40: 0 | E40: 2000 | G40: =IF(OR(C40<D40,C40>E40),1,0)
A41: Opening headcount - Sales & Marketing | B41: FTE | C41: 130 | D41: 0 | E41: 2000 | G41: =IF(OR(C41<D41,C41>E41),1,0)
A42: Opening headcount - G&A | B42: FTE | C42: 50 | D42: 0 | E42: 2000 | G42: =IF(OR(C42<D42,C42>E42),1,0)
...

Sheet Inputs_Scenarios
A1: Inputs_Scenarios - scenario values for every scenario-driven input
A2: Blue cells are inputs. The live column on Inputs_Drivers picks one of these columns via the selector.
A4: Driver | B4: Unit | C4: Base | D4: Upside | E4: Downside | F4: Custom
A5: Growth
A6: New Enterprise logos per month | B6: #/mo | C6: 3 | D6: 3.6 | E6: 2.2 | F6: 3
A7: New Mid-market logos per month | B7: #/mo | C7: 14 | D7: 16 | E7: 10 | F7: 14
A8: Annual growth in new-logo volume | B8: % p.a. | C8: 0.05 | D8: 0.1 | E8: 0 | F8: 0.05
A9: Pricing
A10: Enterprise ACV (new logos) | B10: GBP k | C10: 210 | D10: 220 | E10: 195 | F10: 210
A11: Mid-market ACV (new logos) | B11: GBP k | C11: 26 | D11: 27 | E11: 23 | F11: 26
A12: Annual price uplift on new-logo ACV | B12: % p.a. | C12: 0.03 | D12: 0.04 | E12: 0.01 | F12: 0.03
A13: Retention
A14: Enterprise annual expansion | B14: % of ARR | C14: 0.14 | D14: 0.17 | E14: 0.09 | F14: 0.14
A15: Mid-market annual expansion | B15: % of ARR | C15: 0.07 | D15: 0.09 | E15: 0.04 | F15: 0.07
A16: Enterprise annual gross churn | B16: % of ARR | C16: 0.06 | D16: 0.05 | E16: 0.1 | F16: 0.06
A17: Mid-market annual gross churn | B17: % of ARR | C17: 0.12 | D17: 0.1 | E17: 0.18 | F17: 0.12
A18: People (hiring plan)
A19: R&D net hires per month | B19: FTE/mo | C19: 2.5 | D19: 3 | E19: 1 | F19: 2.5
A20: Sales & Marketing net hires per month | B20: FTE/mo | C20: 3 | D20: 4 | E20: 1 | F20: 3
A21: G&A net hires per month | B21: FTE/mo | C21: 0.8 | D21: 1 | E21: 0.3 | F21: 0.8
A22: Customer Success net hires per month | B22: FTE/mo | C22: 1.5 | D22: 2 | E22: 0.8 | F22: 1.5
A23: Cash
A24: Customer payment terms (DSO) | B24: days | C24: 45 | D24: 40 | E24: 60 | F24: 45
A25: Acquisition: Vaultline scenario drivers
A26: Vaultline new logos per month | B26: #/mo | C26: 1.6 | D26: 2 | E26: 1 | F26: 1.6
A27: Vaultline annual expansion | B27: % of ARR | C27: 0.08 | D27: 0.1 | E27: 0.05 | F27: 0.08
A28: Vaultline annual gross churn | B28: % of ARR | C28: 0.06 | D28: 0.05 | E28: 0.12 | F28: 0.06
A29: Synergies achieved | B29: % of plan | C29: 1 | D29: 1.2 | E29: 0.4 | F29: 1

Sheet Rev_Build
A1: Rev_Build - ARR waterfall and customers by segment
A2: GBP thousands unless stated. Blue = input, black = formula, green = link to another tab.
A3: Period # | C3: =COLUMN()-COLUMN($N$1) | D3: =COLUMN()-COLUMN($N$1) | E3: =COLUMN()-COLUMN($N$1) | F3: =COLUMN()-COLUMN($N$1) | G3: =COLUMN()-COLUMN($N$1) | H3: =COLUMN()-COLUMN($N$1) | I3: =COLUMN()-COLUMN($N$1) | J3: =COLUMN()-COLUMN($N$1) | ... AL3: =COLUMN()-COLUMN($N$1) | AN3: Annual | AO3: Annual
A4: Period ending | C4: =EOMONTH(inp_model_start,C3-1) | D4: =EOMONTH(inp_model_start,D3-1) | E4: =EOMONTH(inp_model_start,E3-1) | F4: =EOMONTH(inp_model_start,F3-1) | G4: =EOMONTH(inp_model_start,G3-1) | H4: =EOMONTH(inp_model_start,H3-1) | I4: =EOMONTH(inp_model_start,I3-1) | J4: =EOMONTH(inp_model_start,J3-1) | ... AL4: =EOMONTH(inp_model_start,AL3-1) | AN4: ="FY"&(YEAR(inp_model_start)+AN5-1) | AO4: ="FY"&(YEAR(inp_model_start)+AO5-1)
A5: Year | C5: =IF(C3<1,0,ROUNDUP(C3/12,0)) | D5: =IF(D3<1,0,ROUNDUP(D3/12,0)) | E5: =IF(E3<1,0,ROUNDUP(E3/12,0)) | F5: =IF(F3<1,0,ROUNDUP(F3/12,0)) | G5: =IF(G3<1,0,ROUNDUP(G3/12,0)) | H5: =IF(H3<1,0,ROUNDUP(H3/12,0)) | I5: =IF(I3<1,0,ROUNDUP(I3/12,0)) | J5: =IF(J3<1,0,ROUNDUP(J3/12,0)) | ... AL5: =IF(AL3<1,0,ROUNDUP(AL3/12,0)) | AN5: =COLUMN()-COLUMN($AM$1) | AO5: =COLUMN()-COLUMN($AM$1)
A6: Quarter | C6: =IF(C3<1,0,ROUNDUP(C3/3,0)) | D6: =IF(D3<1,0,ROUNDUP(D3/3,0)) | E6: =IF(E3<1,0,ROUNDUP(E3/3,0)) | F6: =IF(F3<1,0,ROUNDUP(F3/3,0)) | G6: =IF(G3<1,0,ROUNDUP(G3/3,0)) | H6: =IF(H3<1,0,ROUNDUP(H3/3,0)) | I6: =IF(I3<1,0,ROUNDUP(I3/3,0)) | J6: =IF(J3<1,0,ROUNDUP(J3/3,0)) | ... AL6: =IF(AL3<1,0,ROUNDUP(AL3/3,0))
A8: Volume and price drivers
A9: ACV price factor | B9: x | O9: =(1+inp_price_uplift)^(O$5-1) | P9: =(1+inp_price_uplift)^(P$5-1) | Q9: =(1+inp_price_uplift)^(Q$5-1) | R9: =(1+inp_price_uplift)^(R$5-1) | S9: =(1+inp_price_uplift)^(S$5-1) | T9: =(1+inp_price_uplift)^(T$5-1) | U9: =(1+inp_price_uplift)^(U$5-1) | V9: =(1+inp_price_uplift)^(V$5-1) | ... AL9: =(1+inp_price_uplift)^(AL$5-1) | AN9: =INDEX($O9:$AL9,1,AN$5*12) | AO9: =INDEX($O9:$AL9,1,AO$5*12)
A10: New-logo volume factor | B10: x | O10: =(1+inp_logo_growth)^((O$3-1)/12) | P10: =(1+inp_logo_growth)^((P$3-1)/12) | Q10: =(1+inp_logo_growth)^((Q$3-1)/12) | R10: =(1+inp_logo_growth)^((R$3-1)/12) | S10: =(1+inp_logo_growth)^((S$3-1)/12) | T10: =(1+inp_logo_growth)^((T$3-1)/12) | U10: =(1+inp_logo_growth)^((U$3-1)/12) | V10: =(1+inp_logo_growth)^((V$3-1)/12) | ... AL10: =(1+inp_logo_growth)^((AL$3-1)/12) | AN10: =INDEX($O10:$AL10,1,AN$5*12) | AO10: =INDEX($O10:$AL10,1,AO$5*12)
A11: New logos - Enterprise | B11: # | O11: =inp_logos_ent*O10 | P11: =inp_logos_ent*P10 | Q11: =inp_logos_ent*Q10 | R11: =inp_logos_ent*R10 | S11: =inp_logos_ent*S10 | T11: =inp_logos_ent*T10 | U11: =inp_logos_ent*U10 | V11: =inp_logos_ent*V10 | ... AL11: =inp_logos_ent*AL10 | AN11: =SUMIF($O$5:$AL$5,AN$5,$O11:$AL11) | AO11: =SUMIF($O$5:$AL$5,AO$5,$O11:$AL11)
A12: ACV of new logos - Enterprise | B12: GBP k | O12: =inp_acv_ent*O9 | P12: =inp_acv_ent*P9 | Q12: =inp_acv_ent*Q9 | R12: =inp_acv_ent*R9 | S12: =inp_acv_ent*S9 | T12: =inp_acv_ent*T9 | U12: =inp_acv_ent*U9 | V12: =inp_acv_ent*V9 | ... AL12: =inp_acv_ent*AL9 | AN12: =INDEX($O12:$AL12,1,AN$5*12) | AO12: =INDEX($O12:$AL12,1,AO$5*12)
A13: Monthly gross churn rate - Enterprise | B13: %/mo | O13: =1-(1-inp_churn_ent)^(1/12) | P13: =1-(1-inp_churn_ent)^(1/12) | Q13: =1-(1-inp_churn_ent)^(1/12) | R13: =1-(1-inp_churn_ent)^(1/12) | S13: =1-(1-inp_churn_ent)^(1/12) | T13: =1-(1-inp_churn_ent)^(1/12) | U13: =1-(1-inp_churn_ent)^(1/12) | V13: =1-(1-inp_churn_ent)^(1/12) | ... AL13: =1-(1-inp_churn_ent)^(1/12) | AN13: =INDEX($O13:$AL13,1,AN$5*12) | AO13: =INDEX($O13:$AL13,1,AO$5*12)
A14: Monthly expansion rate - Enterprise | B14: %/mo | O14: =(1+inp_exp_ent)^(1/12)-1 | P14: =(1+inp_exp_ent)^(1/12)-1 | Q14: =(1+inp_exp_ent)^(1/12)-1 | R14: =(1+inp_exp_ent)^(1/12)-1 | S14: =(1+inp_exp_ent)^(1/12)-1 | T14: =(1+inp_exp_ent)^(1/12)-1 | U14: =(1+inp_exp_ent)^(1/12)-1 | V14: =(1+inp_exp_ent)^(1/12)-1 | ... AL14: =(1+inp_exp_ent)^(1/12)-1 | AN14: =INDEX($O14:$AL14,1,AN$5*12) | AO14: =INDEX($O14:$AL14,1,AO$5*12)
A15: New logos - Mid-market | B15: # | O15: =inp_logos_mid*O10 | P15: =inp_logos_mid*P10 | Q15: =inp_logos_mid*Q10 | R15: =inp_logos_mid*R10 | S15: =inp_logos_mid*S10 | T15: =inp_logos_mid*T10 | U15: =inp_logos_mid*U10 | V15: =inp_logos_mid*V10 | ... AL15: =inp_logos_mid*AL10 | AN15: =SUMIF($O$5:$AL$5,AN$5,$O15:$AL15) | AO15: =SUMIF($O$5:$AL$5,AO$5,$O15:$AL15)
A16: ACV of new logos - Mid-market | B16: GBP k | O16: =inp_acv_mid*O9 | P16: =inp_acv_mid*P9 | Q16: =inp_acv_mid*Q9 | R16: =inp_acv_mid*R9 | S16: =inp_acv_mid*S9 | T16: =inp_acv_mid*T9 | U16: =inp_acv_mid*U9 | V16: =inp_acv_mid*V9 | ... AL16: =inp_acv_mid*AL9 | AN16: =INDEX($O16:$AL16,1,AN$5*12) | AO16: =INDEX($O16:$AL16,1,AO$5*12)
A17: Monthly gross churn rate - Mid-market | B17: %/mo | O17: =1-(1-inp_churn_mid)^(1/12) | P17: =1-(1-inp_churn_mid)^(1/12) | Q17: =1-(1-inp_churn_mid)^(1/12) | R17: =1-(1-inp_churn_mid)^(1/12) | S17: =1-(1-inp_churn_mid)^(1/12) | T17: =1-(1-inp_churn_mid)^(1/12) | U17: =1-(1-inp_churn_mid)^(1/12) | V17: =1-(1-inp_churn_mid)^(1/12) | ... AL17: =1-(1-inp_churn_mid)^(1/12) | AN17: =INDEX($O17:$AL17,1,AN$5*12) | AO17: =INDEX($O17:$AL17,1,AO$5*12)
A18: Monthly expansion rate - Mid-market | B18: %/mo | O18: =(1+inp_exp_mid)^(1/12)-1 | P18: =(1+inp_exp_mid)^(1/12)-1 | Q18: =(1+inp_exp_mid)^(1/12)-1 | R18: =(1+inp_exp_mid)^(1/12)-1 | S18: =(1+inp_exp_mid)^(1/12)-1 | T18: =(1+inp_exp_mid)^(1/12)-1 | U18: =(1+inp_exp_mid)^(1/12)-1 | V18: =(1+inp_exp_mid)^(1/12)-1 | ... AL18: =(1+inp_exp_mid)^(1/12)-1 | AN18: =INDEX($O18:$AL18,1,AN$5*12) | AO18: =INDEX($O18:$AL18,1,AO$5*12)
A20: ARR waterfall - Enterprise
A21: Opening ARR | B21: GBP k | O21: =N25 | P21: =O25 | Q21: =P25 | R21: =Q25 | S21: =R25 | T21: =S25 | U21: =T25 | V21: =U25 | ... AL21: =AK25 | AN21: =INDEX($O21:$AL21,1,(AN$5-1)*12+1) | AO21: =INDEX($O21:$AL21,1,(AO$5-1)*12+1)
A22: + New logos | B22: GBP k | O22: =O11*O12 | P22: =P11*P12 | Q22: =Q11*Q12 | R22: =R11*R12 | S22: =S11*S12 | T22: =T11*T12 | U22: =U11*U12 | V22: =V11*V12 | ... AL22: =AL11*AL12 | AN22: =SUMIF($O$5:$AL$5,AN$5,$O22:$AL22) | AO22: =SUMIF($O$5:$AL$5,AO$5,$O22:$AL22)
A23: + Expansion | B23: GBP k | O23: =O21*O14 | P23: =P21*P14 | Q23: =Q21*Q14 | R23: =R21*R14 | S23: =S21*S14 | T23: =T21*T14 | U23: =U21*U14 | V23: =V21*V14 | ... AL23: =AL21*AL14 | AN23: =SUMIF($O$5:$AL$5,AN$5,$O23:$AL23) | AO23: =SUMIF($O$5:$AL$5,AO$5,$O23:$AL23)
A24: - Churn | B24: GBP k | O24: =-O21*O13 | P24: =-P21*P13 | Q24: =-Q21*Q13 | R24: =-R21*R13 | S24: =-S21*S13 | T24: =-T21*T13 | U24: =-U21*U13 | V24: =-V21*V13 | ... AL24: =-AL21*AL13 | AN24: =SUMIF($O$5:$AL$5,AN$5,$O24:$AL24) | AO24: =SUMIF($O$5:$AL$5,AO$5,$O24:$AL24)
A25: Closing ARR | B25: GBP k | N25: =inp_arr_open_ent | O25: =SUM(O21:O24) | P25: =SUM(P21:P24) | Q25: =SUM(Q21:Q24) | R25: =SUM(R21:R24) | S25: =SUM(S21:S24) | T25: =SUM(T21:T24) | U25: =SUM(U21:U24) | V25: =SUM(V21:V24) | ... AL25: =SUM(AL21:AL24) | AN25: =INDEX($O25:$AL25,1,AN$5*12) | AO25: =INDEX($O25:$AL25,1,AO$5*12)
A26: Opening customers | B26: # | O26: =N29 | P26: =O29 | Q26: =P29 | R26: =Q29 | S26: =R29 | T26: =S29 | U26: =T29 | V26: =U29 | ... AL26: =AK29 | AN26: =INDEX($O26:$AL26,1,(AN$5-1)*12+1) | AO26: =INDEX($O26:$AL26,1,(AO$5-1)*12+1)
A27: + New customers | B27: # | O27: =O11 | P27: =P11 | Q27: =Q11 | R27: =R11 | S27: =S11 | T27: =T11 | U27: =U11 | V27: =V11 | ... AL27: =AL11 | AN27: =SUMIF($O$5:$AL$5,AN$5,$O27:$AL27) | AO27: =SUMIF($O$5:$AL$5,AO$5,$O27:$AL27)
A28: - Churned customers | B28: # | O28: =-O26*O13 | P28: =-P26*P13 | Q28: =-Q26*Q13 | R28: =-R26*R13 | S28: =-S26*S13 | T28: =-T26*T13 | U28: =-U26*U13 | V28: =-V26*V13 | ... AL28: =-AL26*AL13 | AN28: =SUMIF($O$5:$AL$5,AN$5,$O28:$AL28) | AO28: =SUMIF($O$5:$AL$5,AO$5,$O28:$AL28)
A29: Closing customers | B29: # | N29: =inp_cust_open_ent | O29: =SUM(O26:O28) | P29: =SUM(P26:P28) | Q29: =SUM(Q26:Q28) | R29: =SUM(R26:R28) | S29: =SUM(S26:S28) | T29: =SUM(T26:T28) | U29: =SUM(U26:U28) | V29: =SUM(V26:V28) | ... AL29: =SUM(AL26:AL28) | AN29: =INDEX($O29:$AL29,1,AN$5*12) | AO29: =INDEX($O29:$AL29,1,AO$5*12)
A31: ARR waterfall - Mid-market
A32: Opening ARR | B32: GBP k | O32: =N36 | P32: =O36 | Q32: =P36 | R32: =Q36 | S32: =R36 | T32: =S36 | U32: =T36 | V32: =U36 | ... AL32: =AK36 | AN32: =INDEX($O32:$AL32,1,(AN$5-1)*12+1) | AO32: =INDEX($O32:$AL32,1,(AO$5-1)*12+1)
A33: + New logos | B33: GBP k | O33: =O15*O16 | P33: =P15*P16 | Q33: =Q15*Q16 | R33: =R15*R16 | S33: =S15*S16 | T33: =T15*T16 | U33: =U15*U16 | V33: =V15*V16 | ... AL33: =AL15*AL16 | AN33: =SUMIF($O$5:$AL$5,AN$5,$O33:$AL33) | AO33: =SUMIF($O$5:$AL$5,AO$5,$O33:$AL33)
A34: + Expansion | B34: GBP k | O34: =O32*O18 | P34: =P32*P18 | Q34: =Q32*Q18 | R34: =R32*R18 | S34: =S32*S18 | T34: =T32*T18 | U34: =U32*U18 | V34: =V32*V18 | ... AL34: =AL32*AL18 | AN34: =SUMIF($O$5:$AL$5,AN$5,$O34:$AL34) | AO34: =SUMIF($O$5:$AL$5,AO$5,$O34:$AL34)
A35: - Churn | B35: GBP k | O35: =-O32*O17 | P35: =-P32*P17 | Q35: =-Q32*Q17 | R35: =-R32*R17 | S35: =-S32*S17 | T35: =-T32*T17 | U35: =-U32*U17 | V35: =-V32*V17 | ... AL35: =-AL32*AL17 | AN35: =SUMIF($O$5:$AL$5,AN$5,$O35:$AL35) | AO35: =SUMIF($O$5:$AL$5,AO$5,$O35:$AL35)
A36: Closing ARR | B36: GBP k | N36: =inp_arr_open_mid | O36: =SUM(O32:O35) | P36: =SUM(P32:P35) | Q36: =SUM(Q32:Q35) | R36: =SUM(R32:R35) | S36: =SUM(S32:S35) | T36: =SUM(T32:T35) | U36: =SUM(U32:U35) | V36: =SUM(V32:V35) | ... AL36: =SUM(AL32:AL35) | AN36: =INDEX($O36:$AL36,1,AN$5*12) | AO36: =INDEX($O36:$AL36,1,AO$5*12)
A37: Opening customers | B37: # | O37: =N40 | P37: =O40 | Q37: =P40 | R37: =Q40 | S37: =R40 | T37: =S40 | U37: =T40 | V37: =U40 | ... AL37: =AK40 | AN37: =INDEX($O37:$AL37,1,(AN$5-1)*12+1) | AO37: =INDEX($O37:$AL37,1,(AO$5-1)*12+1)
A38: + New customers | B38: # | O38: =O15 | P38: =P15 | Q38: =Q15 | R38: =R15 | S38: =S15 | T38: =T15 | U38: =U15 | V38: =V15 | ... AL38: =AL15 | AN38: =SUMIF($O$5:$AL$5,AN$5,$O38:$AL38) | AO38: =SUMIF($O$5:$AL$5,AO$5,$O38:$AL38)
A39: - Churned customers | B39: # | O39: =-O37*O17 | P39: =-P37*P17 | Q39: =-Q37*Q17 | R39: =-R37*R17 | S39: =-S37*S17 | T39: =-T37*T17 | U39: =-U37*U17 | V39: =-V37*V17 | ... AL39: =-AL37*AL17 | AN39: =SUMIF($O$5:$AL$5,AN$5,$O39:$AL39) | AO39: =SUMIF($O$5:$AL$5,AO$5,$O39:$AL39)
A40: Closing customers | B40: # | N40: =inp_cust_open_mid | O40: =SUM(O37:O39) | P40: =SUM(P37:P39) | Q40: =SUM(Q37:Q39) | R40: =SUM(R37:R39) | S40: =SUM(S37:S39) | T40: =SUM(T37:T39) | U40: =SUM(U37:U39) | V40: =SUM(V37:V39) | ... AL40: =SUM(AL37:AL39) | AN40: =INDEX($O40:$AL40,1,AN$5*12) | AO40: =INDEX($O40:$AL40,1,AO$5*12)
A42: Total company
A43: Opening ARR | B43: GBP k | O43: =O21+O32 | P43: =P21+P32 | Q43: =Q21+Q32 | R43: =R21+R32 | S43: =S21+S32 | T43: =T21+T32 | U43: =U21+U32 | V43: =V21+V32 | ... AL43: =AL21+AL32 | AN43: =INDEX($O43:$AL43,1,(AN$5-1)*12+1) | AO43: =INDEX($O43:$AL43,1,(AO$5-1)*12+1)
A44: + New logos | B44: GBP k | O44: =O22+O33 | P44: =P22+P33 | Q44: =Q22+Q33 | R44: =R22+R33 | S44: =S22+S33 | T44: =T22+T33 | U44: =U22+U33 | V44: =V22+V33 | ... AL44: =AL22+AL33 | AN44: =SUMIF($O$5:$AL$5,AN$5,$O44:$AL44) | AO44: =SUMIF($O$5:$AL$5,AO$5,$O44:$AL44)
...

Sheet Rev_Rec
A1: Rev_Rec - billings, ratable revenue (IFRS 15) and deferred revenue
A2: GBP thousands unless stated. Blue = input, black = formula, green = link to another tab.
A3: Period # | C3: =COLUMN()-COLUMN($N$1) | D3: =COLUMN()-COLUMN($N$1) | E3: =COLUMN()-COLUMN($N$1) | F3: =COLUMN()-COLUMN($N$1) | G3: =COLUMN()-COLUMN($N$1) | H3: =COLUMN()-COLUMN($N$1) | I3: =COLUMN()-COLUMN($N$1) | J3: =COLUMN()-COLUMN($N$1) | ... AL3: =COLUMN()-COLUMN($N$1) | AN3: Annual | AO3: Annual
A4: Period ending | C4: =EOMONTH(inp_model_start,C3-1) | D4: =EOMONTH(inp_model_start,D3-1) | E4: =EOMONTH(inp_model_start,E3-1) | F4: =EOMONTH(inp_model_start,F3-1) | G4: =EOMONTH(inp_model_start,G3-1) | H4: =EOMONTH(inp_model_start,H3-1) | I4: =EOMONTH(inp_model_start,I3-1) | J4: =EOMONTH(inp_model_start,J3-1) | ... AL4: =EOMONTH(inp_model_start,AL3-1) | AN4: ="FY"&(YEAR(inp_model_start)+AN5-1) | AO4: ="FY"&(YEAR(inp_model_start)+AO5-1)
A5: Year | C5: =IF(C3<1,0,ROUNDUP(C3/12,0)) | D5: =IF(D3<1,0,ROUNDUP(D3/12,0)) | E5: =IF(E3<1,0,ROUNDUP(E3/12,0)) | F5: =IF(F3<1,0,ROUNDUP(F3/12,0)) | G5: =IF(G3<1,0,ROUNDUP(G3/12,0)) | H5: =IF(H3<1,0,ROUNDUP(H3/12,0)) | I5: =IF(I3<1,0,ROUNDUP(I3/12,0)) | J5: =IF(J3<1,0,ROUNDUP(J3/12,0)) | ... AL5: =IF(AL3<1,0,ROUNDUP(AL3/12,0)) | AN5: =COLUMN()-COLUMN($AM$1) | AO5: =COLUMN()-COLUMN($AM$1)
A6: Quarter | C6: =IF(C3<1,0,ROUNDUP(C3/3,0)) | D6: =IF(D3<1,0,ROUNDUP(D3/3,0)) | E6: =IF(E3<1,0,ROUNDUP(E3/3,0)) | F6: =IF(F3<1,0,ROUNDUP(F3/3,0)) | G6: =IF(G3<1,0,ROUNDUP(G3/3,0)) | H6: =IF(H3<1,0,ROUNDUP(H3/3,0)) | I6: =IF(I3<1,0,ROUNDUP(I3/3,0)) | J6: =IF(J3<1,0,ROUNDUP(J3/3,0)) | ... AL6: =IF(AL3<1,0,ROUNDUP(AL3/3,0))
A8: Subscription invoices raised (annual upfront). Columns C:N hold the opening-year billing history
A9: Invoices raised - Enterprise | B9: GBP k | C9: =inp_arr_open_ent/12 | D9: =inp_arr_open_ent/12 | E9: =inp_arr_open_ent/12 | F9: =inp_arr_open_ent/12 | G9: =inp_arr_open_ent/12 | H9: =inp_arr_open_ent/12 | I9: =inp_arr_open_ent/12 | J9: =inp_arr_open_ent/12 | ... N9: =inp_arr_open_ent/12 | O9: =Rev_Build!O22+(1+inp_exp_ent-inp_churn_ent)*C9 | P9: =Rev_Build!P22+(1+inp_exp_ent-inp_churn_ent)*D9 | Q9: =Rev_Build!Q22+(1+inp_exp_ent-inp_churn_ent)*E9 | R9: =Rev_Build!R22+(1+inp_exp_ent-inp_churn_ent)*F9 | S9: =Rev_Build!S22+(1+inp_exp_ent-inp_churn_ent)*G9 | T9: =Rev_Build!T22+(1+inp_exp_ent-inp_churn_ent)*H9 | U9: =Rev_Build!U22+(1+inp_exp_ent-inp_churn_ent)*I9 | V9: =Rev_Build!V22+(1+inp_exp_ent-inp_churn_ent)*J9 | ... AL9: =Rev_Build!AL22+(1+inp_exp_ent-inp_churn_ent)*Z9 | AN9: =SUMIF($O$5:$AL$5,AN$5,$O9:$AL9) | AO9: =SUMIF($O$5:$AL$5,AO$5,$O9:$AL9)
A10: Invoices raised - Mid-market | B10: GBP k | C10: =inp_arr_open_mid/12 | D10: =inp_arr_open_mid/12 | E10: =inp_arr_open_mid/12 | F10: =inp_arr_open_mid/12 | G10: =inp_arr_open_mid/12 | H10: =inp_arr_open_mid/12 | I10: =inp_arr_open_mid/12 | J10: =inp_arr_open_mid/12 | ... N10: =inp_arr_open_mid/12 | O10: =Rev_Build!O33+(1+inp_exp_mid-inp_churn_mid)*C10 | P10: =Rev_Build!P33+(1+inp_exp_mid-inp_churn_mid)*D10 | Q10: =Rev_Build!Q33+(1+inp_exp_mid-inp_churn_mid)*E10 | R10: =Rev_Build!R33+(1+inp_exp_mid-inp_churn_mid)*F10 | S10: =Rev_Build!S33+(1+inp_exp_mid-inp_churn_mid)*G10 | T10: =Rev_Build!T33+(1+inp_exp_mid-inp_churn_mid)*H10 | U10: =Rev_Build!U33+(1+inp_exp_mid-inp_churn_mid)*I10 | V10: =Rev_Build!V33+(1+inp_exp_mid-inp_churn_mid)*J10 | ... AL10: =Rev_Build!AL33+(1+inp_exp_mid-inp_churn_mid)*Z10 | AN10: =SUMIF($O$5:$AL$5,AN$5,$O10:$AL10) | AO10: =SUMIF($O$5:$AL$5,AO$5,$O10:$AL10)
A11: Total subscription invoices | B11: GBP k | C11: =C9+C10 | D11: =D9+D10 | E11: =E9+E10 | F11: =F9+F10 | G11: =G9+G10 | H11: =H9+H10 | I11: =I9+I10 | J11: =J9+J10 | ... AL11: =AL9+AL10 | AN11: =SUMIF($O$5:$AL$5,AN$5,$O11:$AL11) | AO11: =SUMIF($O$5:$AL$5,AO$5,$O11:$AL11)
A12: Unexpired share of each historic invoice at opening date | B12: x | C12: =(C$3+11)/12 | D12: =(D$3+11)/12 | E12: =(E$3+11)/12 | F12: =(F$3+11)/12 | G12: =(G$3+11)/12 | H12: =(H$3+11)/12 | I12: =(I$3+11)/12 | J12: =(J$3+11)/12 | ... N12: =(N$3+11)/12
A14: Implementation fees (separate performance obligation, recognised over 3 months)
A15: Implementation fees billed | B15: GBP k | O15: =inp_impl_fee_pct*Rev_Build!O22 | P15: =inp_impl_fee_pct*Rev_Build!P22 | Q15: =inp_impl_fee_pct*Rev_Build!Q22 | R15: =inp_impl_fee_pct*Rev_Build!R22 | S15: =inp_impl_fee_pct*Rev_Build!S22 | T15: =inp_impl_fee_pct*Rev_Build!T22 | U15: =inp_impl_fee_pct*Rev_Build!U22 | V15: =inp_impl_fee_pct*Rev_Build!V22 | ... AL15: =inp_impl_fee_pct*Rev_Build!AL22 | AN15: =SUMIF($O$5:$AL$5,AN$5,$O15:$AL15) | AO15: =SUMIF($O$5:$AL$5,AO$5,$O15:$AL15)
A17: Revenue recognised
A18: Subscription revenue - Enterprise (each invoice over 12 months) | B18: GBP k | O18: =SUM(D9:O9)/12 | P18: =SUM(E9:P9)/12 | Q18: =SUM(F9:Q9)/12 | R18: =SUM(G9:R9)/12 | S18: =SUM(H9:S9)/12 | T18: =SUM(I9:T9)/12 | U18: =SUM(J9:U9)/12 | V18: =SUM(K9:V9)/12 | ... AL18: =SUM(AA9:AL9)/12 | AN18: =SUMIF($O$5:$AL$5,AN$5,$O18:$AL18) | AO18: =SUMIF($O$5:$AL$5,AO$5,$O18:$AL18)
A19: Subscription revenue - Mid-market (each invoice over 12 months) | B19: GBP k | O19: =SUM(D10:O10)/12 | P19: =SUM(E10:P10)/12 | Q19: =SUM(F10:Q10)/12 | R19: =SUM(G10:R10)/12 | S19: =SUM(H10:S10)/12 | T19: =SUM(I10:T10)/12 | U19: =SUM(J10:U10)/12 | V19: =SUM(K10:V10)/12 | ... AL19: =SUM(AA10:AL10)/12 | AN19: =SUMIF($O$5:$AL$5,AN$5,$O19:$AL19) | AO19: =SUMIF($O$5:$AL$5,AO$5,$O19:$AL19)
A20: Total subscription revenue | B20: GBP k | O20: =O18+O19 | P20: =P18+P19 | Q20: =Q18+Q19 | R20: =R18+R19 | S20: =S18+S19 | T20: =T18+T19 | U20: =U18+U19 | V20: =V18+V19 | ... AL20: =AL18+AL19 | AN20: =SUMIF($O$5:$AL$5,AN$5,$O20:$AL20) | AO20: =SUMIF($O$5:$AL$5,AO$5,$O20:$AL20)
A21: Implementation revenue | B21: GBP k | O21: =SUM(M15:O15)/3 | P21: =SUM(N15:P15)/3 | Q21: =SUM(O15:Q15)/3 | R21: =SUM(P15:R15)/3 | S21: =SUM(Q15:S15)/3 | T21: =SUM(R15:T15)/3 | U21: =SUM(S15:U15)/3 | V21: =SUM(T15:V15)/3 | ... AL21: =SUM(AJ15:AL15)/3 | AN21: =SUMIF($O$5:$AL$5,AN$5,$O21:$AL21) | AO21: =SUMIF($O$5:$AL$5,AO$5,$O21:$AL21)
A22: Total revenue | B22: GBP k | O22: =O20+O21 | P22: =P20+P21 | Q22: =Q20+Q21 | R22: =R20+R21 | S22: =S20+S21 | T22: =T20+T21 | U22: =U20+U21 | V22: =V20+V21 | ... AL22: =AL20+AL21 | AN22: =SUMIF($O$5:$AL$5,AN$5,$O22:$AL22) | AO22: =SUMIF($O$5:$AL$5,AO$5,$O22:$AL22)
A23: Total billings | B23: GBP k | N23: =N11 | O23: =O11+O15 | P23: =P11+P15 | Q23: =Q11+Q15 | R23: =R11+R15 | S23: =S11+S15 | T23: =T11+T15 | U23: =U11+U15 | V23: =V11+V15 | ... AL23: =AL11+AL15 | AN23: =SUMIF($O$5:$AL$5,AN$5,$O23:$AL23) | AO23: =SUMIF($O$5:$AL$5,AO$5,$O23:$AL23)
A25: Deferred revenue roll-forward
A26: Subscription: opening | B26: GBP k | O26: =N29 | P26: =O29 | Q26: =P29 | R26: =Q29 | S26: =R29 | T26: =S29 | U26: =T29 | V26: =U29 | ... AL26: =AK29 | AN26: =INDEX($O26:$AL26,1,(AN$5-1)*12+1) | AO26: =INDEX($O26:$AL26,1,(AO$5-1)*12+1)
A27: + Invoices raised | B27: GBP k | O27: =O11 | P27: =P11 | Q27: =Q11 | R27: =R11 | S27: =S11 | T27: =T11 | U27: =U11 | V27: =V11 | ... AL27: =AL11 | AN27: =SUMIF($O$5:$AL$5,AN$5,$O27:$AL27) | AO27: =SUMIF($O$5:$AL$5,AO$5,$O27:$AL27)
A28: - Revenue recognised | B28: GBP k | O28: =-O20 | P28: =-P20 | Q28: =-Q20 | R28: =-R20 | S28: =-S20 | T28: =-T20 | U28: =-U20 | V28: =-V20 | ... AL28: =-AL20 | AN28: =SUMIF($O$5:$AL$5,AN$5,$O28:$AL28) | AO28: =SUMIF($O$5:$AL$5,AO$5,$O28:$AL28)
A29: Subscription: closing | B29: GBP k | N29: =SUMPRODUCT(C11:N11,C12:N12) | O29: =SUM(O26:O28) | P29: =SUM(P26:P28) | Q29: =SUM(Q26:Q28) | R29: =SUM(R26:R28) | S29: =SUM(S26:S28) | T29: =SUM(T26:T28) | U29: =SUM(U26:U28) | V29: =SUM(V26:V28) | ... AL29: =SUM(AL26:AL28) | AN29: =INDEX($O29:$AL29,1,AN$5*12) | AO29: =INDEX($O29:$AL29,1,AO$5*12)
A30: Implementation: opening | B30: GBP k | O30: =N33 | P30: =O33 | Q30: =P33 | R30: =Q33 | S30: =R33 | T30: =S33 | U30: =T33 | V30: =U33 | ... AL30: =AK33 | AN30: =INDEX($O30:$AL30,1,(AN$5-1)*12+1) | AO30: =INDEX($O30:$AL30,1,(AO$5-1)*12+1)
A31: + Fees billed | B31: GBP k | O31: =O15 | P31: =P15 | Q31: =Q15 | R31: =R15 | S31: =S15 | T31: =T15 | U31: =U15 | V31: =V15 | ... AL31: =AL15 | AN31: =SUMIF($O$5:$AL$5,AN$5,$O31:$AL31) | AO31: =SUMIF($O$5:$AL$5,AO$5,$O31:$AL31)
A32: - Revenue recognised | B32: GBP k | O32: =-O21 | P32: =-P21 | Q32: =-Q21 | R32: =-R21 | S32: =-S21 | T32: =-T21 | U32: =-U21 | V32: =-V21 | ... AL32: =-AL21 | AN32: =SUMIF($O$5:$AL$5,AN$5,$O32:$AL32) | AO32: =SUMIF($O$5:$AL$5,AO$5,$O32:$AL32)
A33: Implementation: closing | B33: GBP k | N33: =inp_open_defrev_impl | O33: =SUM(O30:O32) | P33: =SUM(P30:P32) | Q33: =SUM(Q30:Q32) | R33: =SUM(R30:R32) | S33: =SUM(S30:S32) | T33: =SUM(T30:T32) | U33: =SUM(U30:U32) | V33: =SUM(V30:V32) | ... AL33: =SUM(AL30:AL32) | AN33: =INDEX($O33:$AL33,1,AN$5*12) | AO33: =INDEX($O33:$AL33,1,AO$5*12)
A34: Total deferred revenue | B34: GBP k | N34: =N29+N33 | O34: =O29+O33 | P34: =P29+P33 | Q34: =Q29+Q33 | R34: =R29+R33 | S34: =S29+S33 | T34: =T29+T33 | U34: =U29+U33 | ... AL34: =AL29+AL33 | AN34: =INDEX($O34:$AL34,1,AN$5*12) | AO34: =INDEX($O34:$AL34,1,AO$5*12)
A36: Trade receivables (payment terms)
A37: Trade receivables | B37: GBP k | N37: =inp_open_ar | O37: =O23*MIN(1,inp_dso/30)+N23*MAX(0,MIN(1,(inp_dso-30)/30)) | P37: =P23*MIN(1,inp_dso/30)+O23*MAX(0,MIN(1,(inp_dso-30)/30)) | Q37: =Q23*MIN(1,inp_dso/30)+P23*MAX(0,MIN(1,(inp_dso-30)/30)) | R37: =R23*MIN(1,inp_dso/30)+Q23*MAX(0,MIN(1,(inp_dso-30)/30)) | S37: =S23*MIN(1,inp_dso/30)+R23*MAX(0,MIN(1,(inp_dso-30)/30)) | T37: =T23*MIN(1,inp_dso/30)+S23*MAX(0,MIN(1,(inp_dso-30)/30)) | U37: =U23*MIN(1,inp_dso/30)+T23*MAX(0,MIN(1,(inp_dso-30)/30)) | V37: =V23*MIN(1,inp_dso/30)+U23*MAX(0,MIN(1,(inp_dso-30)/30)) | ... AL37: =AL23*MIN(1,inp_dso/30)+AK23*MAX(0,MIN(1,(inp_dso-30)/30)) | AN37: =INDEX($O37:$AL37,1,AN$5*12) | AO37: =INDEX($O37:$AL37,1,AO$5*12)
A39: Memo
A40: Subscription revenue / (closing ARR / 12) | B40: % | O40: =O20/(Rev_Build!O47/12) | P40: =P20/(Rev_Build!P47/12) | Q40: =Q20/(Rev_Build!Q47/12) | R40: =R20/(Rev_Build!R47/12) | S40: =S20/(Rev_Build!S47/12) | T40: =T20/(Rev_Build!T47/12) | U40: =U20/(Rev_Build!U47/12) | V40: =V20/(Rev_Build!V47/12) | ... AL40: =AL20/(Rev_Build!AL47/12)

Sheet Headcount_Opex
A1: Headcount_Opex - headcount by function, payroll and non-headcount opex
A2: GBP thousands unless stated. Blue = input, black = formula, green = link to another tab.
A3: Period # | C3: =COLUMN()-COLUMN($N$1) | D3: =COLUMN()-COLUMN($N$1) | E3: =COLUMN()-COLUMN($N$1) | F3: =COLUMN()-COLUMN($N$1) | G3: =COLUMN()-COLUMN($N$1) | H3: =COLUMN()-COLUMN($N$1) | I3: =COLUMN()-COLUMN($N$1) | J3: =COLUMN()-COLUMN($N$1) | ... AL3: =COLUMN()-COLUMN($N$1) | AN3: Annual | AO3: Annual
A4: Period ending | C4: =EOMONTH(inp_model_start,C3-1) | D4: =EOMONTH(inp_model_start,D3-1) | E4: =EOMONTH(inp_model_start,E3-1) | F4: =EOMONTH(inp_model_start,F3-1) | G4: =EOMONTH(inp_model_start,G3-1) | H4: =EOMONTH(inp_model_start,H3-1) | I4: =EOMONTH(inp_model_start,I3-1) | J4: =EOMONTH(inp_model_start,J3-1) | ... AL4: =EOMONTH(inp_model_start,AL3-1) | AN4: ="FY"&(YEAR(inp_model_start)+AN5-1) | AO4: ="FY"&(YEAR(inp_model_start)+AO5-1)
A5: Year | C5: =IF(C3<1,0,ROUNDUP(C3/12,0)) | D5: =IF(D3<1,0,ROUNDUP(D3/12,0)) | E5: =IF(E3<1,0,ROUNDUP(E3/12,0)) | F5: =IF(F3<1,0,ROUNDUP(F3/12,0)) | G5: =IF(G3<1,0,ROUNDUP(G3/12,0)) | H5: =IF(H3<1,0,ROUNDUP(H3/12,0)) | I5: =IF(I3<1,0,ROUNDUP(I3/12,0)) | J5: =IF(J3<1,0,ROUNDUP(J3/12,0)) | ... AL5: =IF(AL3<1,0,ROUNDUP(AL3/12,0)) | AN5: =COLUMN()-COLUMN($AM$1) | AO5: =COLUMN()-COLUMN($AM$1)
A6: Quarter | C6: =IF(C3<1,0,ROUNDUP(C3/3,0)) | D6: =IF(D3<1,0,ROUNDUP(D3/3,0)) | E6: =IF(E3<1,0,ROUNDUP(E3/3,0)) | F6: =IF(F3<1,0,ROUNDUP(F3/3,0)) | G6: =IF(G3<1,0,ROUNDUP(G3/3,0)) | H6: =IF(H3<1,0,ROUNDUP(H3/3,0)) | I6: =IF(I3<1,0,ROUNDUP(I3/3,0)) | J6: =IF(J3<1,0,ROUNDUP(J3/3,0)) | ... AL6: =IF(AL3<1,0,ROUNDUP(AL3/3,0))
A8: Headcount - R&D
A9: Opening FTE | B9: FTE | O9: =N11 | P9: =O11 | Q9: =P11 | R9: =Q11 | S9: =R11 | T9: =S11 | U9: =T11 | V9: =U11 | ... AL9: =AK11 | AN9: =INDEX($O9:$AL9,1,(AN$5-1)*12+1) | AO9: =INDEX($O9:$AL9,1,(AO$5-1)*12+1)
A10: + Net hires | B10: FTE | O10: =inp_hires_rd | P10: =inp_hires_rd | Q10: =inp_hires_rd | R10: =inp_hires_rd | S10: =inp_hires_rd | T10: =inp_hires_rd | U10: =inp_hires_rd | V10: =inp_hires_rd | ... AL10: =inp_hires_rd | AN10: =SUMIF($O$5:$AL$5,AN$5,$O10:$AL10) | AO10: =SUMIF($O$5:$AL$5,AO$5,$O10:$AL10)
A11: Closing FTE | B11: FTE | N11: =inp_heads_open_rd | O11: =O9+O10 | P11: =P9+P10 | Q11: =Q9+Q10 | R11: =R9+R10 | S11: =S9+S10 | T11: =T9+T10 | U11: =U9+U10 | V11: =V9+V10 | ... AL11: =AL9+AL10 | AN11: =INDEX($O11:$AL11,1,AN$5*12) | AO11: =INDEX($O11:$AL11,1,AO$5*12)
A12: Payroll cost (average FTE x loaded cost / 12 x pay-rise factor) | B12: GBP k | O12: =(O9+O11)/2*inp_sal_rd/12*(1+inp_merit)^(O$5-1) | P12: =(P9+P11)/2*inp_sal_rd/12*(1+inp_merit)^(P$5-1) | Q12: =(Q9+Q11)/2*inp_sal_rd/12*(1+inp_merit)^(Q$5-1) | R12: =(R9+R11)/2*inp_sal_rd/12*(1+inp_merit)^(R$5-1) | S12: =(S9+S11)/2*inp_sal_rd/12*(1+inp_merit)^(S$5-1) | T12: =(T9+T11)/2*inp_sal_rd/12*(1+inp_merit)^(T$5-1) | U12: =(U9+U11)/2*inp_sal_rd/12*(1+inp_merit)^(U$5-1) | V12: =(V9+V11)/2*inp_sal_rd/12*(1+inp_merit)^(V$5-1) | ... AL12: =(AL9+AL11)/2*inp_sal_rd/12*(1+inp_merit)^(AL$5-1) | AN12: =SUMIF($O$5:$AL$5,AN$5,$O12:$AL12) | AO12: =SUMIF($O$5:$AL$5,AO$5,$O12:$AL12)
A14: Headcount - Sales & Marketing
A15: Opening FTE | B15: FTE | O15: =N17 | P15: =O17 | Q15: =P17 | R15: =Q17 | S15: =R17 | T15: =S17 | U15: =T17 | V15: =U17 | ... AL15: =AK17 | AN15: =INDEX($O15:$AL15,1,(AN$5-1)*12+1) | AO15: =INDEX($O15:$AL15,1,(AO$5-1)*12+1)
A16: + Net hires | B16: FTE | O16: =inp_hires_sm | P16: =inp_hires_sm | Q16: =inp_hires_sm | R16: =inp_hires_sm | S16: =inp_hires_sm | T16: =inp_hires_sm | U16: =inp_hires_sm | V16: =inp_hires_sm | ... AL16: =inp_hires_sm | AN16: =SUMIF($O$5:$AL$5,AN$5,$O16:$AL16) | AO16: =SUMIF($O$5:$AL$5,AO$5,$O16:$AL16)
A17: Closing FTE | B17: FTE | N17: =inp_heads_open_sm | O17: =O15+O16 | P17: =P15+P16 | Q17: =Q15+Q16 | R17: =R15+R16 | S17: =S15+S16 | T17: =T15+T16 | U17: =U15+U16 | V17: =V15+V16 | ... AL17: =AL15+AL16 | AN17: =INDEX($O17:$AL17,1,AN$5*12) | AO17: =INDEX($O17:$AL17,1,AO$5*12)
A18: Payroll cost (average FTE x loaded cost / 12 x pay-rise factor) | B18: GBP k | O18: =(O15+O17)/2*inp_sal_sm/12*(1+inp_merit)^(O$5-1) | P18: =(P15+P17)/2*inp_sal_sm/12*(1+inp_merit)^(P$5-1) | Q18: =(Q15+Q17)/2*inp_sal_sm/12*(1+inp_merit)^(Q$5-1) | R18: =(R15+R17)/2*inp_sal_sm/12*(1+inp_merit)^(R$5-1) | S18: =(S15+S17)/2*inp_sal_sm/12*(1+inp_merit)^(S$5-1) | T18: =(T15+T17)/2*inp_sal_sm/12*(1+inp_merit)^(T$5-1) | U18: =(U15+U17)/2*inp_sal_sm/12*(1+inp_merit)^(U$5-1) | V18: =(V15+V17)/2*inp_sal_sm/12*(1+inp_merit)^(V$5-1) | ... AL18: =(AL15+AL17)/2*inp_sal_sm/12*(1+inp_merit)^(AL$5-1) | AN18: =SUMIF($O$5:$AL$5,AN$5,$O18:$AL18) | AO18: =SUMIF($O$5:$AL$5,AO$5,$O18:$AL18)
A20: Headcount - G&A
A21: Opening FTE | B21: FTE | O21: =N23 | P21: =O23 | Q21: =P23 | R21: =Q23 | S21: =R23 | T21: =S23 | U21: =T23 | V21: =U23 | ... AL21: =AK23 | AN21: =INDEX($O21:$AL21,1,(AN$5-1)*12+1) | AO21: =INDEX($O21:$AL21,1,(AO$5-1)*12+1)
A22: + Net hires | B22: FTE | O22: =inp_hires_ga | P22: =inp_hires_ga | Q22: =inp_hires_ga | R22: =inp_hires_ga | S22: =inp_hires_ga | T22: =inp_hires_ga | U22: =inp_hires_ga | V22: =inp_hires_ga | ... AL22: =inp_hires_ga | AN22: =SUMIF($O$5:$AL$5,AN$5,$O22:$AL22) | AO22: =SUMIF($O$5:$AL$5,AO$5,$O22:$AL22)
A23: Closing FTE | B23: FTE | N23: =inp_heads_open_ga | O23: =O21+O22 | P23: =P21+P22 | Q23: =Q21+Q22 | R23: =R21+R22 | S23: =S21+S22 | T23: =T21+T22 | U23: =U21+U22 | V23: =V21+V22 | ... AL23: =AL21+AL22 | AN23: =INDEX($O23:$AL23,1,AN$5*12) | AO23: =INDEX($O23:$AL23,1,AO$5*12)
A24: Payroll cost (average FTE x loaded cost / 12 x pay-rise factor) | B24: GBP k | O24: =(O21+O23)/2*inp_sal_ga/12*(1+inp_merit)^(O$5-1) | P24: =(P21+P23)/2*inp_sal_ga/12*(1+inp_merit)^(P$5-1) | Q24: =(Q21+Q23)/2*inp_sal_ga/12*(1+inp_merit)^(Q$5-1) | R24: =(R21+R23)/2*inp_sal_ga/12*(1+inp_merit)^(R$5-1) | S24: =(S21+S23)/2*inp_sal_ga/12*(1+inp_merit)^(S$5-1) | T24: =(T21+T23)/2*inp_sal_ga/12*(1+inp_merit)^(T$5-1) | U24: =(U21+U23)/2*inp_sal_ga/12*(1+inp_merit)^(U$5-1) | V24: =(V21+V23)/2*inp_sal_ga/12*(1+inp_merit)^(V$5-1) | ... AL24: =(AL21+AL23)/2*inp_sal_ga/12*(1+inp_merit)^(AL$5-1) | AN24: =SUMIF($O$5:$AL$5,AN$5,$O24:$AL24) | AO24: =SUMIF($O$5:$AL$5,AO$5,$O24:$AL24)
A26: Headcount - Customer Success
A27: Opening FTE | B27: FTE | O27: =N29 | P27: =O29 | Q27: =P29 | R27: =Q29 | S27: =R29 | T27: =S29 | U27: =T29 | V27: =U29 | ... AL27: =AK29 | AN27: =INDEX($O27:$AL27,1,(AN$5-1)*12+1) | AO27: =INDEX($O27:$AL27,1,(AO$5-1)*12+1)
A28: + Net hires | B28: FTE | O28: =inp_hires_cs | P28: =inp_hires_cs | Q28: =inp_hires_cs | R28: =inp_hires_cs | S28: =inp_hires_cs | T28: =inp_hires_cs | U28: =inp_hires_cs | V28: =inp_hires_cs | ... AL28: =inp_hires_cs | AN28: =SUMIF($O$5:$AL$5,AN$5,$O28:$AL28) | AO28: =SUMIF($O$5:$AL$5,AO$5,$O28:$AL28)
A29: Closing FTE | B29: FTE | N29: =inp_heads_open_cs | O29: =O27+O28 | P29: =P27+P28 | Q29: =Q27+Q28 | R29: =R27+R28 | S29: =S27+S28 | T29: =T27+T28 | U29: =U27+U28 | V29: =V27+V28 | ... AL29: =AL27+AL28 | AN29: =INDEX($O29:$AL29,1,AN$5*12) | AO29: =INDEX($O29:$AL29,1,AO$5*12)
A30: Payroll cost (average FTE x loaded cost / 12 x pay-rise factor) | B30: GBP k | O30: =(O27+O29)/2*inp_sal_cs/12*(1+inp_merit)^(O$5-1) | P30: =(P27+P29)/2*inp_sal_cs/12*(1+inp_merit)^(P$5-1) | Q30: =(Q27+Q29)/2*inp_sal_cs/12*(1+inp_merit)^(Q$5-1) | R30: =(R27+R29)/2*inp_sal_cs/12*(1+inp_merit)^(R$5-1) | S30: =(S27+S29)/2*inp_sal_cs/12*(1+inp_merit)^(S$5-1) | T30: =(T27+T29)/2*inp_sal_cs/12*(1+inp_merit)^(T$5-1) | U30: =(U27+U29)/2*inp_sal_cs/12*(1+inp_merit)^(U$5-1) | V30: =(V27+V29)/2*inp_sal_cs/12*(1+inp_merit)^(V$5-1) | ... AL30: =(AL27+AL29)/2*inp_sal_cs/12*(1+inp_merit)^(AL$5-1) | AN30: =SUMIF($O$5:$AL$5,AN$5,$O30:$AL30) | AO30: =SUMIF($O$5:$AL$5,AO$5,$O30:$AL30)
A32: Totals
A33: Total closing FTE | B33: FTE | N33: =N11+N17+N23+N29 | O33: =O11+O17+O23+O29 | P33: =P11+P17+P23+P29 | Q33: =Q11+Q17+Q23+Q29 | R33: =R11+R17+R23+R29 | S33: =S11+S17+S23+S29 | T33: =T11+T17+T23+T29 | U33: =U11+U17+U23+U29 | ... AL33: =AL11+AL17+AL23+AL29 | AN33: =INDEX($O33:$AL33,1,AN$5*12) | AO33: =INDEX($O33:$AL33,1,AO$5*12)
A34: Total payroll | B34: GBP k | O34: =O12+O18+O24+O30 | P34: =P12+P18+P24+P30 | Q34: =Q12+Q18+Q24+Q30 | R34: =R12+R18+R24+R30 | S34: =S12+S18+S24+S30 | T34: =T12+T18+T24+T30 | U34: =U12+U18+U24+U30 | V34: =V12+V18+V24+V30 | ... AL34: =AL12+AL18+AL24+AL30 | AN34: =SUMIF($O$5:$AL$5,AN$5,$O34:$AL34) | AO34: =SUMIF($O$5:$AL$5,AO$5,$O34:$AL34)
A36: Non-headcount opex
A37: Marketing programmes | B37: GBP k | O37: =inp_marketing_m | P37: =inp_marketing_m | Q37: =inp_marketing_m | R37: =inp_marketing_m | S37: =inp_marketing_m | T37: =inp_marketing_m | U37: =inp_marketing_m | V37: =inp_marketing_m | ... AL37: =inp_marketing_m | AN37: =SUMIF($O$5:$AL$5,AN$5,$O37:$AL37) | AO37: =SUMIF($O$5:$AL$5,AO$5,$O37:$AL37)
A38: R&D non-headcount | B38: GBP k | O38: =inp_rd_other_m | P38: =inp_rd_other_m | Q38: =inp_rd_other_m | R38: =inp_rd_other_m | S38: =inp_rd_other_m | T38: =inp_rd_other_m | U38: =inp_rd_other_m | V38: =inp_rd_other_m | ... AL38: =inp_rd_other_m | AN38: =SUMIF($O$5:$AL$5,AN$5,$O38:$AL38) | AO38: =SUMIF($O$5:$AL$5,AO$5,$O38:$AL38)
A39: G&A non-headcount | B39: GBP k | O39: =inp_ga_other_m | P39: =inp_ga_other_m | Q39: =inp_ga_other_m | R39: =inp_ga_other_m | S39: =inp_ga_other_m | T39: =inp_ga_other_m | U39: =inp_ga_other_m | V39: =inp_ga_other_m | ... AL39: =inp_ga_other_m | AN39: =SUMIF($O$5:$AL$5,AN$5,$O39:$AL39) | AO39: =SUMIF($O$5:$AL$5,AO$5,$O39:$AL39)
A40: Sales commission earned (cash; accounting treatment on Contract_Costs) | B40: GBP k | O40: =inp_commission_pct*(Rev_Build!O44+Rev_Build!O45) | P40: =inp_commission_pct*(Rev_Build!P44+Rev_Build!P45) | Q40: =inp_commission_pct*(Rev_Build!Q44+Rev_Build!Q45) | R40: =inp_commission_pct*(Rev_Build!R44+Rev_Build!R45) | S40: =inp_commission_pct*(Rev_Build!S44+Rev_Build!S45) | T40: =inp_commission_pct*(Rev_Build!T44+Rev_Build!T45) | U40: =inp_commission_pct*(Rev_Build!U44+Rev_Build!U45) | V40: =inp_commission_pct*(Rev_Build!V44+Rev_Build!V45) | ... AL40: =inp_commission_pct*(Rev_Build!AL44+Rev_Build!AL45) | AN40: =SUMIF($O$5:$AL$5,AN$5,$O40:$AL40) | AO40: =SUMIF($O$5:$AL$5,AO$5,$O40:$AL40)
A42: Operating expense by function (Customer Success payroll sits in COGS)
A43: R&D | B43: GBP k | O43: =O12+O38 | P43: =P12+P38 | Q43: =Q12+Q38 | R43: =R12+R38 | S43: =S12+S38 | T43: =T12+T38 | U43: =U12+U38 | V43: =V12+V38 | ... AL43: =AL12+AL38 | AN43: =SUMIF($O$5:$AL$5,AN$5,$O43:$AL43) | AO43: =SUMIF($O$5:$AL$5,AO$5,$O43:$AL43)
A44: Sales & Marketing | B44: GBP k | O44: =O18+O37+Contract_Costs!O20 | P44: =P18+P37+Contract_Costs!P20 | Q44: =Q18+Q37+Contract_Costs!Q20 | R44: =R18+R37+Contract_Costs!R20 | S44: =S18+S37+Contract_Costs!S20 | T44: =T18+T37+Contract_Costs!T20 | U44: =U18+U37+Contract_Costs!U20 | V44: =V18+V37+Contract_Costs!V20 | ... AL44: =AL18+AL37+Contract_Costs!AL20 | AN44: =SUMIF($O$5:$AL$5,AN$5,$O44:$AL44) | AO44: =SUMIF($O$5:$AL$5,AO$5,$O44:$AL44)
A45: G&A | B45: GBP k | O45: =O24+O39 | P45: =P24+P39 | Q45: =Q24+Q39 | R45: =R24+R39 | S45: =S24+S39 | T45: =T24+T39 | U45: =U24+U39 | V45: =V24+V39 | ... AL45: =AL24+AL39 | AN45: =SUMIF($O$5:$AL$5,AN$5,$O45:$AL45) | AO45: =SUMIF($O$5:$AL$5,AO$5,$O45:$AL45)
A46: Total operating expense | B46: GBP k | O46: =SUM(O43:O45) | P46: =SUM(P43:P45) | Q46: =SUM(Q43:Q45) | R46: =SUM(R43:R45) | S46: =SUM(S43:S45) | T46: =SUM(T43:T45) | U46: =SUM(U43:U45) | V46: =SUM(V43:V45) | ... AL46: =SUM(AL43:AL45) | AN46: =SUMIF($O$5:$AL$5,AN$5,$O46:$AL46) | AO46: =SUMIF($O$5:$AL$5,AO$5,$O46:$AL46)

Sheet Contract_Costs
A1: Contract_Costs - capitalised sales commission (IFRS 15.91)
A2: GBP thousands unless stated. Blue = input, black = formula, green = link to another tab.
A3: Period # | C3: =COLUMN()-COLUMN($N$1) | D3: =COLUMN()-COLUMN($N$1) | E3: =COLUMN()-COLUMN($N$1) | F3: =COLUMN()-COLUMN($N$1) | G3: =COLUMN()-COLUMN($N$1) | H3: =COLUMN()-COLUMN($N$1) | I3: =COLUMN()-COLUMN($N$1) | J3: =COLUMN()-COLUMN($N$1) | ... AL3: =COLUMN()-COLUMN($N$1) | AN3: Annual | AO3: Annual
A4: Period ending | C4: =EOMONTH(inp_model_start,C3-1) | D4: =EOMONTH(inp_model_start,D3-1) | E4: =EOMONTH(inp_model_start,E3-1) | F4: =EOMONTH(inp_model_start,F3-1) | G4: =EOMONTH(inp_model_start,G3-1) | H4: =EOMONTH(inp_model_start,H3-1) | I4: =EOMONTH(inp_model_start,I3-1) | J4: =EOMONTH(inp_model_start,J3-1) | ... AL4: =EOMONTH(inp_model_start,AL3-1) | AN4: ="FY"&(YEAR(inp_model_start)+AN5-1) | AO4: ="FY"&(YEAR(inp_model_start)+AO5-1)
A5: Year | C5: =IF(C3<1,0,ROUNDUP(C3/12,0)) | D5: =IF(D3<1,0,ROUNDUP(D3/12,0)) | E5: =IF(E3<1,0,ROUNDUP(E3/12,0)) | F5: =IF(F3<1,0,ROUNDUP(F3/12,0)) | G5: =IF(G3<1,0,ROUNDUP(G3/12,0)) | H5: =IF(H3<1,0,ROUNDUP(H3/12,0)) | I5: =IF(I3<1,0,ROUNDUP(I3/12,0)) | J5: =IF(J3<1,0,ROUNDUP(J3/12,0)) | ... AL5: =IF(AL3<1,0,ROUNDUP(AL3/12,0)) | AN5: =COLUMN()-COLUMN($AM$1) | AO5: =COLUMN()-COLUMN($AM$1)
A6: Quarter | C6: =IF(C3<1,0,ROUNDUP(C3/3,0)) | D6: =IF(D3<1,0,ROUNDUP(D3/3,0)) | E6: =IF(E3<1,0,ROUNDUP(E3/3,0)) | F6: =IF(F3<1,0,ROUNDUP(F3/3,0)) | G6: =IF(G3<1,0,ROUNDUP(G3/3,0)) | H6: =IF(H3<1,0,ROUNDUP(H3/3,0)) | I6: =IF(I3<1,0,ROUNDUP(I3/3,0)) | J6: =IF(J3<1,0,ROUNDUP(J3/3,0)) | ... AL6: =IF(AL3<1,0,ROUNDUP(AL3/3,0))
A8: Commission earned and treatment
A9: Commission earned (cash cost) | B9: GBP k | O9: =Headcount_Opex!O40 | P9: =Headcount_Opex!P40 | Q9: =Headcount_Opex!Q40 | R9: =Headcount_Opex!R40 | S9: =Headcount_Opex!S40 | T9: =Headcount_Opex!T40 | U9: =Headcount_Opex!U40 | V9: =Headcount_Opex!V40 | ... AL9: =Headcount_Opex!AL40 | AN9: =SUMIF($O$5:$AL$5,AN$5,$O9:$AL9) | AO9: =SUMIF($O$5:$AL$5,AO$5,$O9:$AL9)
A10: Capitalised | B10: GBP k | O10: =inp_capitalise_commission*O9 | P10: =inp_capitalise_commission*P9 | Q10: =inp_capitalise_commission*Q9 | R10: =inp_capitalise_commission*R9 | S10: =inp_capitalise_commission*S9 | T10: =inp_capitalise_commission*T9 | U10: =inp_capitalise_commission*U9 | V10: =inp_capitalise_commission*V9 | ... AL10: =inp_capitalise_commission*AL9 | AN10: =SUMIF($O$5:$AL$5,AN$5,$O10:$AL10) | AO10: =SUMIF($O$5:$AL$5,AO$5,$O10:$AL10)
A11: Expensed immediately | B11: GBP k | O11: =O9-O10 | P11: =P9-P10 | Q11: =Q9-Q10 | R11: =R9-R10 | S11: =S9-S10 | T11: =T9-T10 | U11: =U9-U10 | V11: =V9-V10 | ... AL11: =AL9-AL10 | AN11: =SUMIF($O$5:$AL$5,AN$5,$O11:$AL11) | AO11: =SUMIF($O$5:$AL$5,AO$5,$O11:$AL11)
A13: Asset roll-forward
A14: Opening asset | B14: GBP k | O14: =N17 | P14: =O17 | Q14: =P17 | R14: =Q17 | S14: =R17 | T14: =S17 | U14: =T17 | V14: =U17 | ... AL14: =AK17 | AN14: =INDEX($O14:$AL14,1,(AN$5-1)*12+1) | AO14: =INDEX($O14:$AL14,1,(AO$5-1)*12+1)
A15: + Capitalised | B15: GBP k | O15: =O10 | P15: =P10 | Q15: =Q10 | R15: =R10 | S15: =S10 | T15: =T10 | U15: =U10 | V15: =V10 | ... AL15: =AL10 | AN15: =SUMIF($O$5:$AL$5,AN$5,$O15:$AL15) | AO15: =SUMIF($O$5:$AL$5,AO$5,$O15:$AL15)
A16: - Amortisation | B16: GBP k | O16: =-O14/inp_cc_life | P16: =-P14/inp_cc_life | Q16: =-Q14/inp_cc_life | R16: =-R14/inp_cc_life | S16: =-S14/inp_cc_life | T16: =-T14/inp_cc_life | U16: =-U14/inp_cc_life | V16: =-V14/inp_cc_life | ... AL16: =-AL14/inp_cc_life | AN16: =SUMIF($O$5:$AL$5,AN$5,$O16:$AL16) | AO16: =SUMIF($O$5:$AL$5,AO$5,$O16:$AL16)
A17: Closing asset | B17: GBP k | N17: =inp_open_cca | O17: =SUM(O14:O16) | P17: =SUM(P14:P16) | Q17: =SUM(Q14:Q16) | R17: =SUM(R14:R16) | S17: =SUM(S14:S16) | T17: =SUM(T14:T16) | U17: =SUM(U14:U16) | V17: =SUM(V14:V16) | ... AL17: =SUM(AL14:AL16) | AN17: =INDEX($O17:$AL17,1,AN$5*12) | AO17: =INDEX($O17:$AL17,1,AO$5*12)
A19: Charge to the income statement (S&M)
A20: Commission expense = expensed now + amortisation | B20: GBP k | O20: =O11-O16 | P20: =P11-P16 | Q20: =Q11-Q16 | R20: =R11-R16 | S20: =S11-S16 | T20: =T11-T16 | U20: =U11-U16 | V20: =V11-V16 | ... AL20: =AL11-AL16 | AN20: =SUMIF($O$5:$AL$5,AN$5,$O20:$AL20) | AO20: =SUMIF($O$5:$AL$5,AO$5,$O20:$AL20)

Sheet COGS
A1: COGS - hosting, licences, support and services; gross margin by stream
A2: GBP thousands unless stated. Blue = input, black = formula, green = link to another tab.
A3: Period # | C3: =COLUMN()-COLUMN($N$1) | D3: =COLUMN()-COLUMN($N$1) | E3: =COLUMN()-COLUMN($N$1) | F3: =COLUMN()-COLUMN($N$1) | G3: =COLUMN()-COLUMN($N$1) | H3: =COLUMN()-COLUMN($N$1) | I3: =COLUMN()-COLUMN($N$1) | J3: =COLUMN()-COLUMN($N$1) | ... AL3: =COLUMN()-COLUMN($N$1) | AN3: Annual | AO3: Annual
A4: Period ending | C4: =EOMONTH(inp_model_start,C3-1) | D4: =EOMONTH(inp_model_start,D3-1) | E4: =EOMONTH(inp_model_start,E3-1) | F4: =EOMONTH(inp_model_start,F3-1) | G4: =EOMONTH(inp_model_start,G3-1) | H4: =EOMONTH(inp_model_start,H3-1) | I4: =EOMONTH(inp_model_start,I3-1) | J4: =EOMONTH(inp_model_start,J3-1) | ... AL4: =EOMONTH(inp_model_start,AL3-1) | AN4: ="FY"&(YEAR(inp_model_start)+AN5-1) | AO4: ="FY"&(YEAR(inp_model_start)+AO5-1)
A5: Year | C5: =IF(C3<1,0,ROUNDUP(C3/12,0)) | D5: =IF(D3<1,0,ROUNDUP(D3/12,0)) | E5: =IF(E3<1,0,ROUNDUP(E3/12,0)) | F5: =IF(F3<1,0,ROUNDUP(F3/12,0)) | G5: =IF(G3<1,0,ROUNDUP(G3/12,0)) | H5: =IF(H3<1,0,ROUNDUP(H3/12,0)) | I5: =IF(I3<1,0,ROUNDUP(I3/12,0)) | J5: =IF(J3<1,0,ROUNDUP(J3/12,0)) | ... AL5: =IF(AL3<1,0,ROUNDUP(AL3/12,0)) | AN5: =COLUMN()-COLUMN($AM$1) | AO5: =COLUMN()-COLUMN($AM$1)
A6: Quarter | C6: =IF(C3<1,0,ROUNDUP(C3/3,0)) | D6: =IF(D3<1,0,ROUNDUP(D3/3,0)) | E6: =IF(E3<1,0,ROUNDUP(E3/3,0)) | F6: =IF(F3<1,0,ROUNDUP(F3/3,0)) | G6: =IF(G3<1,0,ROUNDUP(G3/3,0)) | H6: =IF(H3<1,0,ROUNDUP(H3/3,0)) | I6: =IF(I3<1,0,ROUNDUP(I3/3,0)) | J6: =IF(J3<1,0,ROUNDUP(J3/3,0)) | ... AL6: =IF(AL3<1,0,ROUNDUP(AL3/3,0))
A8: Cost of revenue
A9: Hosting (closing customers x cost per customer) | B9: GBP k | O9: =Rev_Build!O29*inp_host_ent+Rev_Build!O40*inp_host_mid | P9: =Rev_Build!P29*inp_host_ent+Rev_Build!P40*inp_host_mid | Q9: =Rev_Build!Q29*inp_host_ent+Rev_Build!Q40*inp_host_mid | R9: =Rev_Build!R29*inp_host_ent+Rev_Build!R40*inp_host_mid | S9: =Rev_Build!S29*inp_host_ent+Rev_Build!S40*inp_host_mid | T9: =Rev_Build!T29*inp_host_ent+Rev_Build!T40*inp_host_mid | U9: =Rev_Build!U29*inp_host_ent+Rev_Build!U40*inp_host_mid | V9: =Rev_Build!V29*inp_host_ent+Rev_Build!V40*inp_host_mid | ... AL9: =Rev_Build!AL29*inp_host_ent+Rev_Build!AL40*inp_host_mid | AN9: =SUMIF($O$5:$AL$5,AN$5,$O9:$AL9) | AO9: =SUMIF($O$5:$AL$5,AO$5,$O9:$AL9)
A10: Third-party licences | B10: GBP k | O10: =inp_licence_pct*Rev_Rec!O20 | P10: =inp_licence_pct*Rev_Rec!P20 | Q10: =inp_licence_pct*Rev_Rec!Q20 | R10: =inp_licence_pct*Rev_Rec!R20 | S10: =inp_licence_pct*Rev_Rec!S20 | T10: =inp_licence_pct*Rev_Rec!T20 | U10: =inp_licence_pct*Rev_Rec!U20 | V10: =inp_licence_pct*Rev_Rec!V20 | ... AL10: =inp_licence_pct*Rev_Rec!AL20 | AN10: =SUMIF($O$5:$AL$5,AN$5,$O10:$AL10) | AO10: =SUMIF($O$5:$AL$5,AO$5,$O10:$AL10)
A11: Customer Success payroll | B11: GBP k | O11: =Headcount_Opex!O30 | P11: =Headcount_Opex!P30 | Q11: =Headcount_Opex!Q30 | R11: =Headcount_Opex!R30 | S11: =Headcount_Opex!S30 | T11: =Headcount_Opex!T30 | U11: =Headcount_Opex!U30 | V11: =Headcount_Opex!V30 | ... AL11: =Headcount_Opex!AL30 | AN11: =SUMIF($O$5:$AL$5,AN$5,$O11:$AL11) | AO11: =SUMIF($O$5:$AL$5,AO$5,$O11:$AL11)
A12: Implementation delivery cost | B12: GBP k | O12: =inp_services_cost_pct*Rev_Rec!O21 | P12: =inp_services_cost_pct*Rev_Rec!P21 | Q12: =inp_services_cost_pct*Rev_Rec!Q21 | R12: =inp_services_cost_pct*Rev_Rec!R21 | S12: =inp_services_cost_pct*Rev_Rec!S21 | T12: =inp_services_cost_pct*Rev_Rec!T21 | U12: =inp_services_cost_pct*Rev_Rec!U21 | V12: =inp_services_cost_pct*Rev_Rec!V21 | ... AL12: =inp_services_cost_pct*Rev_Rec!AL21 | AN12: =SUMIF($O$5:$AL$5,AN$5,$O12:$AL12) | AO12: =SUMIF($O$5:$AL$5,AO$5,$O12:$AL12)
A13: Total COGS | B13: GBP k | O13: =SUM(O9:O12) | P13: =SUM(P9:P12) | Q13: =SUM(Q9:Q12) | R13: =SUM(R9:R12) | S13: =SUM(S9:S12) | T13: =SUM(T9:T12) | U13: =SUM(U9:U12) | V13: =SUM(V9:V12) | ... AL13: =SUM(AL9:AL12) | AN13: =SUMIF($O$5:$AL$5,AN$5,$O13:$AL13) | AO13: =SUMIF($O$5:$AL$5,AO$5,$O13:$AL13)
A15: Gross margin by stream
A16: Subscription revenue | B16: GBP k | O16: =Rev_Rec!O20 | P16: =Rev_Rec!P20 | Q16: =Rev_Rec!Q20 | R16: =Rev_Rec!R20 | S16: =Rev_Rec!S20 | T16: =Rev_Rec!T20 | U16: =Rev_Rec!U20 | V16: =Rev_Rec!V20 | ... AL16: =Rev_Rec!AL20 | AN16: =SUMIF($O$5:$AL$5,AN$5,$O16:$AL16) | AO16: =SUMIF($O$5:$AL$5,AO$5,$O16:$AL16)
A17: Subscription gross profit | B17: GBP k | O17: =O16-O9-O10-O11 | P17: =P16-P9-P10-P11 | Q17: =Q16-Q9-Q10-Q11 | R17: =R16-R9-R10-R11 | S17: =S16-S9-S10-S11 | T17: =T16-T9-T10-T11 | U17: =U16-U9-U10-U11 | V17: =V16-V9-V10-V11 | ... AL17: =AL16-AL9-AL10-AL11 | AN17: =SUMIF($O$5:$AL$5,AN$5,$O17:$AL17) | AO17: =SUMIF($O$5:$AL$5,AO$5,$O17:$AL17)
A18: Subscription gross margin | B18: % | O18: =O17/O16 | P18: =P17/P16 | Q18: =Q17/Q16 | R18: =R17/R16 | S18: =S17/S16 | T18: =T17/T16 | U18: =U17/U16 | V18: =V17/V16 | ... AL18: =AL17/AL16 | AN18: =INDEX($O18:$AL18,1,AN$5*12) | AO18: =INDEX($O18:$AL18,1,AO$5*12)
A19: Implementation revenue | B19: GBP k | O19: =Rev_Rec!O21 | P19: =Rev_Rec!P21 | Q19: =Rev_Rec!Q21 | R19: =Rev_Rec!R21 | S19: =Rev_Rec!S21 | T19: =Rev_Rec!T21 | U19: =Rev_Rec!U21 | V19: =Rev_Rec!V21 | ... AL19: =Rev_Rec!AL21 | AN19: =SUMIF($O$5:$AL$5,AN$5,$O19:$AL19) | AO19: =SUMIF($O$5:$AL$5,AO$5,$O19:$AL19)
A20: Implementation gross profit | B20: GBP k | O20: =O19-O12 | P20: =P19-P12 | Q20: =Q19-Q12 | R20: =R19-R12 | S20: =S19-S12 | T20: =T19-T12 | U20: =U19-U12 | V20: =V19-V12 | ... AL20: =AL19-AL12 | AN20: =SUMIF($O$5:$AL$5,AN$5,$O20:$AL20) | AO20: =SUMIF($O$5:$AL$5,AO$5,$O20:$AL20)
A21: Implementation gross margin | B21: % | O21: =IF(O19=0,0,O20/O19) | P21: =IF(P19=0,0,P20/P19) | Q21: =IF(Q19=0,0,Q20/Q19) | R21: =IF(R19=0,0,R20/R19) | S21: =IF(S19=0,0,S20/S19) | T21: =IF(T19=0,0,T20/T19) | U21: =IF(U19=0,0,U20/U19) | V21: =IF(V19=0,0,V20/V19) | ... AL21: =IF(AL19=0,0,AL20/AL19) | AN21: =INDEX($O21:$AL21,1,AN$5*12) | AO21: =INDEX($O21:$AL21,1,AO$5*12)
A22: Total gross profit | B22: GBP k | O22: =O17+O20 | P22: =P17+P20 | Q22: =Q17+Q20 | R22: =R17+R20 | S22: =S17+S20 | T22: =T17+T20 | U22: =U17+U20 | V22: =V17+V20 | ... AL22: =AL17+AL20 | AN22: =SUMIF($O$5:$AL$5,AN$5,$O22:$AL22) | AO22: =SUMIF($O$5:$AL$5,AO$5,$O22:$AL22)
A23: Blended gross margin | B23: % | O23: =O22/(O16+O19) | P23: =P22/(P16+P19) | Q23: =Q22/(Q16+Q19) | R23: =R22/(R16+R19) | S23: =S22/(S16+S19) | T23: =T22/(T16+T19) | U23: =U22/(U16+U19) | V23: =V22/(V16+V19) | ... AL23: =AL22/(AL16+AL19) | AN23: =INDEX($O23:$AL23,1,AN$5*12) | AO23: =INDEX($O23:$AL23,1,AO$5*12)

Sheet IS
A1: IS - income statement
A2: GBP thousands unless stated. Blue = input, black = formula, green = link to another tab.
A3: Period # | C3: =COLUMN()-COLUMN($N$1) | D3: =COLUMN()-COLUMN($N$1) | E3: =COLUMN()-COLUMN($N$1) | F3: =COLUMN()-COLUMN($N$1) | G3: =COLUMN()-COLUMN($N$1) | H3: =COLUMN()-COLUMN($N$1) | I3: =COLUMN()-COLUMN($N$1) | J3: =COLUMN()-COLUMN($N$1) | ... AL3: =COLUMN()-COLUMN($N$1) | AN3: Annual | AO3: Annual
A4: Period ending | C4: =EOMONTH(inp_model_start,C3-1) | D4: =EOMONTH(inp_model_start,D3-1) | E4: =EOMONTH(inp_model_start,E3-1) | F4: =EOMONTH(inp_model_start,F3-1) | G4: =EOMONTH(inp_model_start,G3-1) | H4: =EOMONTH(inp_model_start,H3-1) | I4: =EOMONTH(inp_model_start,I3-1) | J4: =EOMONTH(inp_model_start,J3-1) | ... AL4: =EOMONTH(inp_model_start,AL3-1) | AN4: ="FY"&(YEAR(inp_model_start)+AN5-1) | AO4: ="FY"&(YEAR(inp_model_start)+AO5-1)
A5: Year | C5: =IF(C3<1,0,ROUNDUP(C3/12,0)) | D5: =IF(D3<1,0,ROUNDUP(D3/12,0)) | E5: =IF(E3<1,0,ROUNDUP(E3/12,0)) | F5: =IF(F3<1,0,ROUNDUP(F3/12,0)) | G5: =IF(G3<1,0,ROUNDUP(G3/12,0)) | H5: =IF(H3<1,0,ROUNDUP(H3/12,0)) | I5: =IF(I3<1,0,ROUNDUP(I3/12,0)) | J5: =IF(J3<1,0,ROUNDUP(J3/12,0)) | ... AL5: =IF(AL3<1,0,ROUNDUP(AL3/12,0)) | AN5: =COLUMN()-COLUMN($AM$1) | AO5: =COLUMN()-COLUMN($AM$1)
A6: Quarter | C6: =IF(C3<1,0,ROUNDUP(C3/3,0)) | D6: =IF(D3<1,0,ROUNDUP(D3/3,0)) | E6: =IF(E3<1,0,ROUNDUP(E3/3,0)) | F6: =IF(F3<1,0,ROUNDUP(F3/3,0)) | G6: =IF(G3<1,0,ROUNDUP(G3/3,0)) | H6: =IF(H3<1,0,ROUNDUP(H3/3,0)) | I6: =IF(I3<1,0,ROUNDUP(I3/3,0)) | J6: =IF(J3<1,0,ROUNDUP(J3/3,0)) | ... AL6: =IF(AL3<1,0,ROUNDUP(AL3/3,0))
A8: Revenue
A9: Subscription - Enterprise | B9: GBP k | O9: =Rev_Rec!O18 | P9: =Rev_Rec!P18 | Q9: =Rev_Rec!Q18 | R9: =Rev_Rec!R18 | S9: =Rev_Rec!S18 | T9: =Rev_Rec!T18 | U9: =Rev_Rec!U18 | V9: =Rev_Rec!V18 | ... AL9: =Rev_Rec!AL18 | AN9: =SUMIF($O$5:$AL$5,AN$5,$O9:$AL9) | AO9: =SUMIF($O$5:$AL$5,AO$5,$O9:$AL9)
A10: Subscription - Mid-market | B10: GBP k | O10: =Rev_Rec!O19 | P10: =Rev_Rec!P19 | Q10: =Rev_Rec!Q19 | R10: =Rev_Rec!R19 | S10: =Rev_Rec!S19 | T10: =Rev_Rec!T19 | U10: =Rev_Rec!U19 | V10: =Rev_Rec!V19 | ... AL10: =Rev_Rec!AL19 | AN10: =SUMIF($O$5:$AL$5,AN$5,$O10:$AL10) | AO10: =SUMIF($O$5:$AL$5,AO$5,$O10:$AL10)
A11: Implementation | B11: GBP k | O11: =Rev_Rec!O21 | P11: =Rev_Rec!P21 | Q11: =Rev_Rec!Q21 | R11: =Rev_Rec!R21 | S11: =Rev_Rec!S21 | T11: =Rev_Rec!T21 | U11: =Rev_Rec!U21 | V11: =Rev_Rec!V21 | ... AL11: =Rev_Rec!AL21 | AN11: =SUMIF($O$5:$AL$5,AN$5,$O11:$AL11) | AO11: =SUMIF($O$5:$AL$5,AO$5,$O11:$AL11)
A12: Total revenue | B12: GBP k | O12: =SUM(O9:O11) | P12: =SUM(P9:P11) | Q12: =SUM(Q9:Q11) | R12: =SUM(R9:R11) | S12: =SUM(S9:S11) | T12: =SUM(T9:T11) | U12: =SUM(U9:U11) | V12: =SUM(V9:V11) | ... AL12: =SUM(AL9:AL11) | AN12: =SUMIF($O$5:$AL$5,AN$5,$O12:$AL12) | AO12: =SUMIF($O$5:$AL$5,AO$5,$O12:$AL12)
A14: Cost of revenue
A15: Hosting | B15: GBP k | O15: =COGS!O9 | P15: =COGS!P9 | Q15: =COGS!Q9 | R15: =COGS!R9 | S15: =COGS!S9 | T15: =COGS!T9 | U15: =COGS!U9 | V15: =COGS!V9 | ... AL15: =COGS!AL9 | AN15: =SUMIF($O$5:$AL$5,AN$5,$O15:$AL15) | AO15: =SUMIF($O$5:$AL$5,AO$5,$O15:$AL15)
